---
layout: post
title: 多线程下异常处理
abbrlink: 2e7b8463dcd04cb8abbb21e391ec9077
tags:
  - 多线程
categories:
  - Mac笔记本
  - 多线程
date: 1719450686866
updated: 1721922507237
---

一个线程中的异常只能在该线程内捕获和处理，而不能直接在另一个线程中捕获。

- 线程的独立性:

> 线程是独立的执行单元，每个线程都有自己的调用栈和执行上下文。当一个线程抛出异常时，该异常会在该线程的调用栈上进行传播，直到找到相应的异常处理器（try-catch 块）或者最终未被捕获导致线程终止。\
> 由于线程之间的调用栈是独立的，一个线程无法访问或干预另一个线程的调用栈，因此也就无法直接捕获另一个线程中的异常。

- 异常的传播机制

> 在单线程程序中，异常会沿着调用栈向上传播，直到找到合适的异常处理器。如果没有找到，程序将会终止。在多线程环境中，异常的传播机制依然是在线程的调用栈内进行的，异常不会跨线程传播。

## 多线程下异常处理方式

1. 在同一线程中捕获异常.

> 在每个线程的执行代码中使用 try-catch 块来捕获异常。

2. 通过共享变量传递异常信息.

```kotlin
import java.util.concurrent.atomic.AtomicReference

val exception = AtomicReference<Throwable?>()

val thread = Thread {
    try {
        // 线程的工作代码
        throw RuntimeException("Something went wrong")
    } catch (e: Throwable) {
        exception.set(e)
    }
}

thread.start()
thread.join() // 等待线程完成

exception.get()?.let {
    println("Caught exception from thread: ${it.message}")
}

```

3. 使用 Future 和 ExecutorService

> 在使用线程池和 Future 的情况下，可以通过 Future.get() 方法捕获线程中的异常。

```kotlin
//FutureTask 用于储存执行结果
val task = FutureTask(object : Callable<String> {
    override fun call(): String {
        println("调用咯:${Thread.currentThread().id}")
        val n = 1 / 0
        return "wtf:$n"
    }

})
val thread = Thread(task)
// start 后立马执行task
thread.start()

try {
    //调用get()才会触发返回值,调用之前task已经执行过了
    task.get()
} catch (e: Exception) {
    e.printStackTrace()
    println("捕获了:${Thread.currentThread().id}")
}
```

![d330ae3e6c2933d0f6b2900d13cb72f3.png](/resources/d1079b25cf8a4f5b8a89bacda5d423cd.png)\
4\. 使用自定义的 `UncaughtExceptionHandler`

```kotlin
val handler = Thread.UncaughtExceptionHandler { t, e ->
    e.printStackTrace()
    println("Caught exception from thread ${t.name}: ${e.message}")
}

val thread = Thread {
    throw RuntimeException("Something went wrong")
}

thread.uncaughtExceptionHandler = handler
thread.start()
//Android 中默认的是这个:是:com.android.internal.os.RuntimeInit$KillApplicationHandler@ba6f1cf
```

![7fe1c2fd6a5b03f89d5b378c3cdd5286.png](/resources/e9ed8e6ac0b142ffbcf86dc9b2490566.png)\
5\. Kotlin 协程中 使用 `CoroutineExceptionHandler`来捕获。

```kotlin
import kotlinx.coroutines.*

val handler = CoroutineExceptionHandler { _, exception ->
    exception.printStackTrace()
    println("Caught exception: ${exception.message}")
}
//当协程中发生“未捕获的异常”时，协程框架会检查上下文中是否存在 CoroutineExceptionHandler，如果存在，则调用其 handleException 方法处理异常
val scope = CoroutineScope(Dispatchers.Default + handler)

scope.launch {
    throw RuntimeException("Something went wrong")
}
Thread.sleep(1000)
```

![736db02c018bec9f456a0e7c8e1a6833.png](/resources/e9755276a1264a8baa384994cf999ce7.png)
